<?xml version="1.0" ?>
<!-- =================================================================================== -->
<!-- |    This document was autogenerated by xacro from hdt_saffir_left.xacro          | -->
<!-- |    EDITING THIS FILE BY HAND IS NOT RECOMMENDED                                 | -->
<!-- =================================================================================== -->
<robot name="hdt_saffir_left" xmlns:xacro="http://www.ros.org/wiki/xacro">
  <!-- materials -->
  <material name="black">
    <color rgba="0.0 0.0 0.0 1.0"/>
  </material>
  <material name="grey">
    <color rgba="0.235294117647 0.235294117647 0.235294117647 1.0"/>
  </material>
  <material name="orange">
    <color rgba="1.0 0.549019607843 0.0 1.0"/>
  </material>
  <material name="maroon">
    <color rgba="0.501960784314 0.0 0.0 1.0"/>
  </material>
  <material name="silver">
    <color rgba="0.752941176471 0.752941176471 0.752941176471 1.0"/>
  </material>
  <!-- ros_control plugin -->
  <gazebo>
    <plugin filename="libgazebo_ros_control.so" name="gazebo_ros_control">
      <robotNamespace>/hdt_saffir</robotNamespace>
      <controlPeriod>0.001</controlPeriod>
      <!-- 1000Hz -->
      <robotSimType>gazebo_ros_control/DefaultRobotHWSim</robotSimType>
    </plugin>
  </gazebo>
  <gazebo reference="base_link">
    <material>Gazebo/White</material>
    <static>true</static>
    <selfCollide>true</selfCollide>
  </gazebo>
  <!-- segment 0 -->
  <!--<link name="world"/>
  <joint name="base_link" type="fixed">
    <origin rpy="0 0 0" xyz="0 0 1"/>
    <parent link="world"/>
    <child link="base_link"/>
  </joint>-->
  <link name="base_link">
  </link>
  <!-- Links -->
  <gazebo reference="pedestal_link">
    <material>Gazebo/FlatBlack</material>
    <selfCollide>true</selfCollide>
  </gazebo>
  <gazebo reference="drive1">
    <material>Gazebo/Grey</material>
    <selfCollide>false</selfCollide>
  </gazebo>
  <gazebo reference="drive2">
    <material>Gazebo/Grey</material>
    <selfCollide>false</selfCollide>
  </gazebo>
  <gazebo reference="shoulder">
    <material>Gazebo/Red</material>
    <selfCollide>false</selfCollide>
  </gazebo>
  <gazebo reference="drive3">
    <material>Gazebo/FlatBlack</material>
    <selfCollide>false</selfCollide>
  </gazebo>
  <gazebo reference="tube">
    <material>Gazebo/Orange</material>
    <selfCollide>false</selfCollide>
  </gazebo>
  <gazebo reference="drive4">
    <material>Gazebo/FlatBlack</material>
    <selfCollide>false</selfCollide>
  </gazebo>
  <gazebo reference="forearm">
    <material>Gazebo/Orange</material>
    <selfCollide>false</selfCollide>
  </gazebo>
  <gazebo reference="drive5">
    <material>Gazebo/Grey</material>
    <selfCollide>false</selfCollide>
  </gazebo>
  <gazebo reference="drive6">
    <material>Gazebo/Grey</material>
    <selfCollide>false</selfCollide>
  </gazebo>
  <gazebo reference="A35">
    <material>Gazebo/Orange</material>
    <selfCollide>false</selfCollide>
  </gazebo>
  <gazebo reference="drive7">
    <material>Gazebo/Grey</material>
    <selfCollide>false</selfCollide>
  </gazebo>
  <gazebo reference="palm">
    <material>Gazebo/Orange</material>
    <selfCollide>false</selfCollide>
  </gazebo>
  <gazebo reference="thumb_base">
    <material>Gazebo/Orange</material>
    <selfCollide>false</selfCollide>
  </gazebo>
  <gazebo reference="thumb_prox">
    <material>Gazebo/White</material>
    <selfCollide>false</selfCollide>
  </gazebo>
  <gazebo reference="thumb_med">
    <material>Gazebo/White</material>
    <selfCollide>false</selfCollide>
  </gazebo>
  <gazebo reference="thumb_dist">
    <material>Gazebo/White</material>
    <selfCollide>false</selfCollide>
  </gazebo>
  <gazebo reference="index_prox">
    <material>Gazebo/White</material>
    <selfCollide>false</selfCollide>
  </gazebo>
  <gazebo reference="index_med">
    <material>Gazebo/White</material>
    <selfCollide>false</selfCollide>
  </gazebo>
  <gazebo reference="index_dist">
    <material>Gazebo/White</material>
    <selfCollide>false</selfCollide>
  </gazebo>
  <gazebo reference="ring_prox">
    <material>Gazebo/White</material>
    <selfCollide>false</selfCollide>
  </gazebo>
  <gazebo reference="ring_med">
    <material>Gazebo/White</material>
    <selfCollide>false</selfCollide>
  </gazebo>
  <gazebo reference="ring_dist">
    <material>Gazebo/White</material>
    <selfCollide>false</selfCollide>
  </gazebo>
  <!-- Joints -->
  <gazebo reference="joint1">
    <implicitSpringDamper>1</implicitSpringDamper>
    <!-- <cfmDamping>1</cfmDamping> -->
  </gazebo>
  <gazebo reference="joint2">
    <implicitSpringDamper>1</implicitSpringDamper>
    <!-- <cfmDamping>1</cfmDamping> -->
  </gazebo>
  <gazebo reference="joint3">
    <implicitSpringDamper>1</implicitSpringDamper>
    <!-- <cfmDamping>1</cfmDamping> -->
  </gazebo>
  <gazebo reference="joint4">
    <implicitSpringDamper>1</implicitSpringDamper>
    <!-- <cfmDamping>1</cfmDamping> -->
  </gazebo>
  <gazebo reference="joint5">
    <implicitSpringDamper>1</implicitSpringDamper>
    <!-- <cfmDamping>1</cfmDamping> -->
  </gazebo>
  <gazebo reference="joint6">
    <implicitSpringDamper>1</implicitSpringDamper>
    <!-- <cfmDamping>1</cfmDamping> -->
  </gazebo>
  <gazebo reference="joint7">
    <implicitSpringDamper>1</implicitSpringDamper>
    <!-- <cfmDamping>1</cfmDamping> -->
  </gazebo>
  <gazebo reference="thumb_base">
    <implicitSpringDamper>1</implicitSpringDamper>
    <!-- <cfmDamping>1</cfmDamping> -->
  </gazebo>
  <gazebo reference="thumb_prox">
    <implicitSpringDamper>1</implicitSpringDamper>
    <!-- <cfmDamping>1</cfmDamping> -->
  </gazebo>
  <gazebo reference="index_prox">
    <implicitSpringDamper>1</implicitSpringDamper>
    <!-- <cfmDamping>1</cfmDamping> -->
  </gazebo>
  <gazebo reference="ring_prox">
    <implicitSpringDamper>1</implicitSpringDamper>
    <!-- <cfmDamping>1</cfmDamping> -->
  </gazebo>
  <!-- mounting plate -->
  <joint name="pedestal_joint" type="fixed">
    <origin rpy="1.57079632679 0 0" xyz="0 0 0"/>
    <parent link="base_link"/>
    <child link="pedestal_link"/>
  </joint>
  <link name="pedestal_link">
    <!--<collision>
        <origin xyz="0 0 0" rpy="0 0 0"/>
        <geometry>
          <mesh filename="package://hdt_saffir_description/meshes/PEDESTAL_ASSEMBLY.STL"/>
        </geometry>
      </collision>-->
    <visual>
      <origin rpy="0 0 0" xyz="0 0 0"/>
      <geometry>
        <mesh filename="package://hdt_saffir_description/meshes/PEDESTAL_ASSEMBLY.STL"/>
      </geometry>
      <material name="black"/>
    </visual>
    <inertial>
      <origin rpy="0 0 0" xyz="0.00824926 0.00007832 0.02192315"/>
      <mass value="0.25375688"/>
      <inertia ixx="0.00014143" ixy="-0.00000016" ixz="-0.00001282" iyy="0.00016740" iyz="0.00000015" izz="0.00020523"/>
    </inertial>
  </link>
  <!-- Drive 1 -->
  <joint name="joint0" type="fixed">
    <origin rpy="-1.57079632679 0 1.57079632679" xyz="0 0 .0891"/>
    <parent link="pedestal_link"/>
    <child link="drive1"/>
  </joint>
  <link name="drive1">
    <!--<collision>
        <origin xyz="0 0 0" rpy="0 0 0"/>
        <geometry>
          <mesh filename="package://hdt_saffir_description/meshes/MK4_MT.STL"/>
        </geometry>
      </collision>-->
    <visual>
      <origin rpy="0 0 0" xyz="0 0 0"/>
      <geometry>
        <mesh filename="package://hdt_saffir_description/meshes/MK4_MT.STL"/>
      </geometry>
      <material name="grey"/>
    </visual>
    <inertial>
      <origin rpy="0 0 0" xyz="-0.00004358 0.00244867 0.00739686"/>
      <mass value="1.73427319"/>
      <inertia ixx="0.00212963" ixy="-0.00000090" ixz="-0.00000052" iyy="0.00199851" iyz="-0.00004418" izz="0.00138126"/>
    </inertial>
  </link>
  <!-- Drive 2 -->
  <joint name="joint1" type="revolute">
    <hdt id="41" inertia="0.1" kmax="20" kmin="10"/>
    <axis xyz="0 -1 0"/>
    <limit effort="180.0" lower="-3.14159265359" upper="1.57079632679" velocity="0.4"/>
    <origin rpy="1.57079632679 0 0" xyz="0 0 -.082642"/>
    <parent link="drive1"/>
    <child link="drive2"/>
    <dynamics damping="0.7" friction="0.01"/>
  </joint>
  <transmission name="tran1">
    <type>transmission_interface/SimpleTransmission</type>
    <joint name="joint1">
      <hardwareInterface>hardware_interface/EffortJointInterface</hardwareInterface>
    </joint>
    <actuator name="motor1">
      <mechanicalReduction>1</mechanicalReduction>
      <hardwareInterface>hardware_interface/EffortJointInterface</hardwareInterface>
    </actuator>
  </transmission>
  <link name="drive2">
    <!--<collision>
        <origin xyz="0 0 0" rpy="0 0 0"/>
        <geometry>
          <mesh filename="package://hdt_saffir_description/meshes/MK4_LT.STL"/>
        </geometry>
      </collision>-->
    <visual>
      <origin rpy="0 0 0" xyz="0 0 0"/>
      <geometry>
        <mesh filename="package://hdt_saffir_description/meshes/MK4_LT.STL"/>
      </geometry>
      <material name="grey"/>
    </visual>
    <inertial>
      <origin rpy="0 0 0" xyz="-0.00003658 0.00177045 0.00631346"/>
      <mass value="1.39278013"/>
      <inertia ixx="0.00159582" ixy="-0.00000077" ixz="-0.00000081" iyy="0.00151230" iyz="-0.00002261" izz="0.00105406"/>
    </inertial>
  </link>
  <!-- Shoulder bracket -->
  <joint name="joint2" type="revolute">
    <hdt id="42" inertia="0.1" kmax="20" kmin="10"/>
    <axis xyz="0 0 -1"/>
    <limit effort="90.0" lower="-3.14159265359" upper="0.25" velocity="0.4"/>
    <origin rpy="0 0 -1.57079632679" xyz="0 0 -.07526"/>
    <parent link="drive2"/>
    <child link="shoulder"/>
    <dynamics damping="0.7" friction="0.01"/>
  </joint>
  <transmission name="tran2">
    <type>transmission_interface/SimpleTransmission</type>
    <joint name="joint2">
      <hardwareInterface>hardware_interface/EffortJointInterface</hardwareInterface>
    </joint>
    <actuator name="motor2">
      <mechanicalReduction>1</mechanicalReduction>
      <hardwareInterface>hardware_interface/EffortJointInterface</hardwareInterface>
    </actuator>
  </transmission>
  <link name="shoulder">
    <!--<collision>
        <origin xyz="0 0 0" rpy="0 0 0"/>
        <geometry>
          <mesh filename="package://hdt_saffir_description/meshes/SHOULDER_BRACKET.STL"/>
        </geometry>
      </collision>-->
    <visual>
      <origin rpy="0 0 0" xyz="0 0 0"/>
      <geometry>
        <mesh filename="package://hdt_saffir_description/meshes/SHOULDER_BRACKET.STL"/>
      </geometry>
      <material name="maroon"/>
    </visual>
    <inertial>
      <origin rpy="0 0 0" xyz="0.00013570 -0.04958110 0.01659126"/>
      <mass value="0.48998269"/>
      <inertia ixx="0.00124111" ixy="-0.00000083" ixz="-0.00000019" iyy="0.00020695" iyz="0.00001359" izz="0.00132624"/>
    </inertial>
  </link>
  <!-- Drive 3 -->
  <joint name="shoulder" type="fixed">
    <origin rpy="-1.57079632679 0 0" xyz="0 -.1 .07526"/>
    <parent link="shoulder"/>
    <child link="drive3"/>
  </joint>
  <link name="drive3">
    <!--<collision>
        <origin xyz="0 0 0" rpy="0 0 0"/>
        <geometry>
          <mesh filename="package://hdt_saffir_description/meshes/MK4_LT.STL"/>
        </geometry>
      </collision>-->
    <visual>
      <origin rpy="0 0 0" xyz="0 0 0"/>
      <geometry>
        <mesh filename="package://hdt_saffir_description/meshes/MK4_LT.STL"/>
      </geometry>
      <material name="grey"/>
    </visual>
    <inertial>
      <origin rpy="0 0 0" xyz="-0.00003658 0.00177045 0.00631346"/>
      <mass value="1.39278013"/>
      <inertia ixx="0.00159582" ixy="-0.00000077" ixz="-0.00000081" iyy="0.00151230" iyz="-0.00002261" izz="0.00105406"/>
    </inertial>
  </link>
  <!-- Proximal tube -->
  <joint name="joint3" type="revolute">
    <hdt id="43" inertia="0.1" kmax="20" kmin="10"/>
    <axis xyz="0 0 -1"/>
    <limit effort="90.0" lower="-3.14159265359" upper="3.14159265359" velocity="0.4"/>
    <origin rpy="-3.14159265359 0 3.14159265359" xyz="0 0 -.1900260"/>
    <parent link="drive3"/>
    <child link="tube"/>
    <dynamics damping="0.01" friction="0.01"/>
  </joint>
  <transmission name="tran3">
    <type>transmission_interface/SimpleTransmission</type>
    <joint name="joint3">
      <hardwareInterface>hardware_interface/EffortJointInterface</hardwareInterface>
    </joint>
    <actuator name="motor3">
      <mechanicalReduction>1</mechanicalReduction>
      <hardwareInterface>hardware_interface/EffortJointInterface</hardwareInterface>
    </actuator>
  </transmission>
  <link name="tube">
    <!--<collision>
        <origin xyz="0 0 0" rpy="0 0 0"/>
        <geometry>
          <mesh filename="package://hdt_saffir_description/meshes/PROXIMAL_TUBE.STL"/>
        </geometry>
      </collision>-->
    <visual>
      <origin rpy="0 0 0" xyz="0 0 0"/>
      <geometry>
        <mesh filename="package://hdt_saffir_description/meshes/PROXIMAL_TUBE.STL"/>
      </geometry>
      <material name="orange"/>
    </visual>
    <inertial>
      <origin rpy="0 0 0" xyz="-0.00003112 0.00004034 -0.06064495"/>
      <mass value="0.30359918"/>
      <inertia ixx="0.00099336" ixy="0.00000000" ixz="-0.00000021" iyy="0.00099312" iyz="-0.00000024" izz="0.00020564"/>
    </inertial>
  </link>
  <!-- Drive 4 -->
  <joint name="tube" type="fixed">
    <origin rpy="-1.57079632679 0 -1.57079632679" xyz="0 0 0.0486304"/>
    <parent link="tube"/>
    <child link="drive4"/>
  </joint>
  <link name="drive4">
    <!--<collision>
        <origin xyz="0 0 0" rpy="0 0 0"/>
        <geometry>
          <mesh filename="package://hdt_saffir_description/meshes/MK4_LT.STL"/>
        </geometry>
      </collision>-->
    <visual>
      <origin rpy="0 0 0" xyz="0 0 0"/>
      <geometry>
        <mesh filename="package://hdt_saffir_description/meshes/MK4_LT.STL"/>
      </geometry>
      <material name="grey"/>
    </visual>
    <inertial>
      <origin rpy="0 0 0" xyz="-0.00003658 0.00177045 0.00631346"/>
      <mass value="1.39278013"/>
      <inertia ixx="0.00159582" ixy="-0.00000077" ixz="-0.00000081" iyy="0.00151230" iyz="-0.00002261" izz="0.00105406"/>
    </inertial>
  </link>
  <!-- Forearm bracket -->
  <joint name="joint4" type="revolute">
    <hdt id="44" inertia="0.1" kmax="20" kmin="10"/>
    <axis xyz="0 0 -1"/>
    <limit effort="90.0" lower="-0.785398163397" upper="3.14159265359" velocity="0.4"/>
    <origin rpy="0 0 1.57079632679" xyz="0 0 -.061820"/>
    <parent link="drive4"/>
    <child link="forearm"/>
    <dynamics damping="0.7" friction="0.01"/>
  </joint>
  <transmission name="tran4">
    <type>transmission_interface/SimpleTransmission</type>
    <joint name="joint4">
      <hardwareInterface>hardware_interface/EffortJointInterface</hardwareInterface>
    </joint>
    <actuator name="motor4">
      <mechanicalReduction>1</mechanicalReduction>
      <hardwareInterface>hardware_interface/EffortJointInterface</hardwareInterface>
    </actuator>
  </transmission>
  <link name="forearm">
    <!--<collision>
        <origin xyz="0 0 0" rpy="0 0 0"/>
        <geometry>
          <mesh filename="package://hdt_saffir_description/meshes/FOREARM_BRACKET.STL"/>
        </geometry>
      </collision>-->
    <visual>
      <origin rpy="0 0 0" xyz="0 0 0"/>
      <geometry>
        <mesh filename="package://hdt_saffir_description/meshes/FOREARM_BRACKET.STL"/>
      </geometry>
      <material name="maroon"/>
    </visual>
    <inertial>
      <origin rpy="0 0 0" xyz="-0.00009916 -0.03803734 0.01245969"/>
      <mass value="0.29009416"/>
      <inertia ixx="0.00060152" ixy="-0.00000038" ixz="0.00000003" iyy="0.00009927" iyz="-0.00000788" izz="0.00065009"/>
    </inertial>
  </link>
  <!-- Drive 5 -->
  <joint name="forearm" type="fixed">
    <origin rpy="-1.57079632679 0 0" xyz="0 -.1 0.0509560"/>
    <parent link="forearm"/>
    <child link="drive5"/>
  </joint>
  <link name="drive5">
    <!--<collision>
        <origin xyz="0 0 0" rpy="0 0 0"/>
        <geometry>
          <mesh filename="package://hdt_saffir_description/meshes/A35_DRIVE.STL"/>
        </geometry>
      </collision>-->
    <visual>
      <origin rpy="0 0 0" xyz="0 0 0"/>
      <geometry>
        <mesh filename="package://hdt_saffir_description/meshes/A35_DRIVE.STL"/>
      </geometry>
      <material name="grey"/>
    </visual>
    <inertial>
      <origin rpy="0 0 0" xyz="0.00000913 0.00110529 -0.01094052"/>
      <mass value="0.30279069"/>
      <inertia ixx="0.00012394" ixy="-0.00000001" ixz="-0.00000007" iyy="0.00011824" iyz="0.00000325" izz="0.00008729"/>
    </inertial>
  </link>
  <!-- Drive 6 -->
  <joint name="joint5" type="revolute">
    <hdt id="45" inertia="0.1" kmax="20" kmin="10"/>
    <axis xyz="0 1 0"/>
    <limit effort="35.0" lower="-3.14159265359" upper="3.14159265359" velocity="2.09439510239"/>
    <origin rpy="1.57079632679 0 -1.57079632679" xyz="0 0 -.067262"/>
    <parent link="drive5"/>
    <child link="drive6"/>
    <dynamics damping="0.7" friction="0.01"/>
  </joint>
  <transmission name="tran5">
    <type>transmission_interface/SimpleTransmission</type>
    <joint name="joint5">
      <hardwareInterface>hardware_interface/EffortJointInterface</hardwareInterface>
    </joint>
    <actuator name="motor5">
      <mechanicalReduction>1</mechanicalReduction>
      <hardwareInterface>hardware_interface/EffortJointInterface</hardwareInterface>
    </actuator>
  </transmission>
  <link name="drive6">
    <!--<collision>
        <origin xyz="0 0 0" rpy="0 0 0"/>
        <geometry>
          <mesh filename="package://hdt_saffir_description/meshes/A35_DRIVE.STL"/>
        </geometry>
      </collision>-->
    <visual>
      <origin rpy="0 0 0" xyz="0 0 0"/>
      <geometry>
        <mesh filename="package://hdt_saffir_description/meshes/A35_DRIVE.STL"/>
      </geometry>
      <material name="grey"/>
    </visual>
    <inertial>
      <origin rpy="0 0 0" xyz="0.00000913 0.00110529 -0.01094052"/>
      <mass value="0.30279069"/>
      <inertia ixx="0.00012394" ixy="-0.00000001" ixz="-0.00000007" iyy="0.00011824" iyz="0.00000325" izz="0.00008729"/>
    </inertial>
  </link>
  <!-- A35 bracket -->
  <joint name="joint6" type="revolute">
    <hdt id="46" inertia="0.1" kmax="20" kmin="10"/>
    <axis xyz="0 0 -1"/>
    <limit effort="35.0" lower="-1.57079632679" upper="1.57079632679" velocity="2.09439510239"/>
    <origin rpy="0 0 0" xyz="0 0 -.0566728"/>
    <parent link="drive6"/>
    <child link="A35"/>
    <dynamics damping="0.7" friction="0.01"/>
  </joint>
  <transmission name="tran6">
    <type>transmission_interface/SimpleTransmission</type>
    <joint name="joint6">
      <hardwareInterface>hardware_interface/EffortJointInterface</hardwareInterface>
    </joint>
    <actuator name="motor6">
      <mechanicalReduction>1</mechanicalReduction>
      <hardwareInterface>hardware_interface/EffortJointInterface</hardwareInterface>
    </actuator>
  </transmission>
  <link name="A35">
    <!--<collision>
        <origin xyz="0 0 0" rpy="0 0 0"/>
        <geometry>
          <mesh filename="package://hdt_saffir_description/meshes/A35_BRACKET.STL"/>
        </geometry>
      </collision>-->
    <visual>
      <origin rpy="0 0 0" xyz="0 0 0"/>
      <geometry>
        <mesh filename="package://hdt_saffir_description/meshes/A35_BRACKET.STL"/>
      </geometry>
      <material name="maroon"/>
    </visual>
    <inertial>
      <origin rpy="0 0 0" xyz="-0.00001212 -0.02930845 0.01300716"/>
      <mass value="0.14250708"/>
      <inertia ixx="0.00011554" ixy="0.00000005" ixz="-0.00000003" iyy="0.00003814" iyz="-0.00000988" izz="0.00012738"/>
    </inertial>
  </link>
  <!-- Drive 7 -->
  <joint name="A35" type="fixed">
    <origin rpy="-1.57079632679 0 0" xyz="0 -.05 .0566728"/>
    <parent link="A35"/>
    <child link="drive7"/>
  </joint>
  <link name="drive7">
    <!--<collision>
        <origin xyz="0 0 0" rpy="0 0 0"/>
        <geometry>
          <mesh filename="package://hdt_saffir_description/meshes/A35_DRIVE.STL"/>
        </geometry>
      </collision>-->
    <visual>
      <origin rpy="0 0 0" xyz="0 0 0"/>
      <geometry>
        <mesh filename="package://hdt_saffir_description/meshes/A35_DRIVE.STL"/>
      </geometry>
      <material name="grey"/>
    </visual>
    <inertial>
      <origin rpy="0 0 0" xyz="0.00000913 0.00110529 -0.01094052"/>
      <mass value="0.30279069"/>
      <inertia ixx="0.00012394" ixy="-0.00000001" ixz="-0.00000007" iyy="0.00011824" iyz="0.00000325" izz="0.00008729"/>
    </inertial>
  </link>
  <!-- endpoint link -->
  <joint name="joint7" type="revolute">
    <hdt id="47" inertia="0.1" kmax="20" kmin="10"/>
    <axis xyz="0 1 0"/>
    <limit effort="35.0" lower="-3.14159265359" upper="3.14159265359" velocity="2.09439510239"/>
    <origin rpy="1.57079632679 0 -3.14159265359" xyz="0 0 -.0421620"/>
    <parent link="drive7"/>
    <child link="end_effector"/>
    <dynamics damping="0.7" friction="0.01"/>
  </joint>
  <transmission name="tran7">
    <type>transmission_interface/SimpleTransmission</type>
    <joint name="joint7">
      <hardwareInterface>hardware_interface/EffortJointInterface</hardwareInterface>
    </joint>
    <actuator name="motor7">
      <mechanicalReduction>1</mechanicalReduction>
      <hardwareInterface>hardware_interface/EffortJointInterface</hardwareInterface>
    </actuator>
  </transmission>
  <link name="end_effector">
    </link>
  <!-- endpoint -->
  <joint name="endpoint_joint" type="fixed">
    <origin rpy="0 0 0" xyz="0 0 0"/>
    <parent link="end_effector"/>
    <child link="endpoint_link"/>
  </joint>
  <link name="endpoint_link">
    </link>
  <!-- palm -->
  <joint name="palm" type="fixed">
    <origin rpy="0 0 0" xyz="0 0 0"/>
    <parent link="endpoint_link"/>
    <child link="palm"/>
  </joint>
  <link name="palm">
    <!--<collision>
        <origin xyz="0 0 -0.6" rpy="0 0 0"/>
        <geometry>
          <mesh filename="package://hdt_saffir_description/meshes/hdt_6dof_palm.STL"/>
        </geometry>
      </collision>-->
    <visual>
      <origin rpy="0 0 0" xyz="0 0 0.0"/>
      <geometry>
        <mesh filename="package://hdt_saffir_description/meshes/hdt_6dof_palm.STL"/>
      </geometry>
      <material name="orange"/>
    </visual>
    <inertial>
      <origin rpy="0 0 0" xyz="0 -0.08326 -0.00539"/>
      <mass value="0.56756"/>
      <inertia ixx="0.001727803" ixy="0.000001205" ixz="0.0" iyy="0.000549457" iyz="-0.000101997" izz="0.001418031"/>
      <!-- <inertia -->
      <!--     ixx="0.01727803" ixy="0.00001205" ixz="0.0" -->
      <!--     iyy="0.00549457" iyz="-0.00101997" -->
      <!--     izz="0.01418031"/> -->
    </inertial>
  </link>
  <!-- thumb base -->
  <joint name="thumb_base" type="revolute">
    <hdt id="50" inertia="0.01" kmax="2" kmin="10"/>
    <axis xyz="0 1 0"/>
    <limit effort="4.0" lower="-1.5708" upper="1.5708" velocity="4.1888"/>
    <origin rpy="0 0 0" xyz="0 -0.05039 0.01529"/>
    <parent link="palm"/>
    <child link="thumb_base"/>
    <dynamics damping="0.7" friction="0.01"/>
  </joint>
  <transmission name="tran10">
    <type>transmission_interface/SimpleTransmission</type>
    <joint name="thumb_base">
      <hardwareInterface>hardware_interface/EffortJointInterface</hardwareInterface>
    </joint>
    <actuator name="motor10">
      <mechanicalReduction>1</mechanicalReduction>
      <hardwareInterface>hardware_interface/EffortJointInterface</hardwareInterface>
    </actuator>
  </transmission>
  <link name="thumb_base">
    <collision>
      <origin rpy="0 0 0" xyz="0 0 0"/>
      <geometry>
        <mesh filename="package://hdt_saffir_description/meshes/hdt_6dof_thumb_base.STL"/>
      </geometry>
    </collision>
    <visual>
      <origin rpy="0 0 0" xyz="0 0 0"/>
      <geometry>
        <mesh filename="package://hdt_saffir_description/meshes/hdt_6dof_thumb_base.STL"/>
      </geometry>
      <material name="orange"/>
    </visual>
    <inertial>
      <origin rpy="0 0 0" xyz="0 -0.02653 0.02207"/>
      <mass value="0.08562"/>
      <!-- <inertia -->
      <!--     ixx="0.0000315" ixy="0.0" ixz="0.0" -->
      <!--     iyy="0.000034299" iyz="0.0" -->
      <!--     izz="0.000022344"/> -->
      <inertia ixx="0.000315" ixy="0.0" ixz="0.0" iyy="0.00034299" iyz="0.0" izz="0.00022344"/>
    </inertial>
  </link>
  <!-- thumb prox -->
  <joint name="thumb_prox" type="revolute">
    <hdt id="51" inertia="0.01" kmax="2" kmin="10"/>
    <axis xyz="1 0 0"/>
    <limit effort="4.0" lower="-0.1" upper="2.1" velocity="4.1888"/>
    <origin rpy="0 0 0" xyz="0.00214 -0.02759 0.05700"/>
    <parent link="thumb_base"/>
    <child link="thumb_prox"/>
    <dynamics damping="0.7" friction="0.01"/>
  </joint>
  <transmission name="tran11">
    <type>transmission_interface/SimpleTransmission</type>
    <joint name="thumb_prox">
      <hardwareInterface>hardware_interface/EffortJointInterface</hardwareInterface>
    </joint>
    <actuator name="motor11">
      <mechanicalReduction>1</mechanicalReduction>
      <hardwareInterface>hardware_interface/EffortJointInterface</hardwareInterface>
    </actuator>
  </transmission>
  <link name="thumb_prox">
    <collision>
      <origin rpy="0 0 0" xyz="0 0 0"/>
      <geometry>
        <mesh filename="package://hdt_saffir_description/meshes/hdt_6dof_thumb_prox.STL"/>
      </geometry>
    </collision>
    <visual>
      <origin rpy="0 0 0" xyz="0 0 0"/>
      <geometry>
        <mesh filename="package://hdt_saffir_description/meshes/hdt_6dof_thumb_prox.STL"/>
      </geometry>
      <material name="orange"/>
    </visual>
    <inertial>
      <origin rpy="0 0 0" xyz="0 0.001 0.02063"/>
      <mass value="0.02523"/>
      <!-- <inertia -->
      <!--     ixx="0.000004718" ixy="0.0" ixz="0.0" -->
      <!--     iyy="0.000005374" iyz="-0.000000071" -->
      <!--     izz="0.000002921"/> -->
      <inertia ixx="0.0004718" ixy="0.0" ixz="0.0" iyy="0.0005374" iyz="-0.0000071" izz="0.0002921"/>
    </inertial>
  </link>
  <!-- thumb med -->
  <joint name="thumb_med" type="fixed">
    <origin rpy="0 0 0" xyz="0 0.00285 0.04341"/>
    <parent link="thumb_prox"/>
    <child link="thumb_med"/>
  </joint>
  <link name="thumb_med">
    <collision>
      <origin rpy="0 0 0" xyz="0 0 0"/>
      <geometry>
        <mesh filename="package://hdt_saffir_description/meshes/hdt_6dof_thumb_med.STL"/>
      </geometry>
    </collision>
    <visual>
      <origin rpy="0 0 0" xyz="0 0 0"/>
      <geometry>
        <mesh filename="package://hdt_saffir_description/meshes/hdt_6dof_thumb_med.STL"/>
      </geometry>
      <material name="black"/>
    </visual>
    <inertial>
      <origin rpy="0 0 0" xyz="0 -0.00353 0.01162"/>
      <mass value="0.0085"/>
      <!-- <inertia -->
      <!--     ixx="0.000001099" ixy="0.0" ixz="0.0" -->
      <!--     iyy="0.000001639" iyz="0.000000096" -->
      <!--     izz="0.000000981"/> -->
      <inertia ixx="0.0001099" ixy="0.0" ixz="0.0" iyy="0.0001639" iyz="0.0000096" izz="0.0000981"/>
    </inertial>
  </link>
  <!-- thumb dist -->
  <joint name="thumb_dist" type="fixed">
    <origin rpy="0 0 0" xyz="0 -0.0009 0.02769"/>
    <parent link="thumb_med"/>
    <child link="thumb_dist"/>
  </joint>
  <link name="thumb_dist">
    <collision>
      <origin rpy="0 0 0" xyz="0 0 0"/>
      <geometry>
        <mesh filename="package://hdt_saffir_description/meshes/hdt_6dof_thumb_dist.STL"/>
      </geometry>
    </collision>
    <visual>
      <origin rpy="0 0 0" xyz="0 0 0"/>
      <geometry>
        <mesh filename="package://hdt_saffir_description/meshes/hdt_6dof_thumb_dist.STL"/>
      </geometry>
      <material name="orange"/>
    </visual>
    <inertial>
      <origin rpy="0 0 0" xyz="0 -0.00131 0.01323"/>
      <mass value="0.0092"/>
      <!-- <inertia -->
      <!--     ixx="0.00000066" ixy="0.0" ixz="0.0" -->
      <!--     iyy="0.000000837" iyz="0.0" -->
      <!--     izz="0.000000695"/> -->
      <inertia ixx="0.00066" ixy="0.0" ixz="0.0" iyy="0.000837" iyz="0.0" izz="0.000695"/>
    </inertial>
  </link>
  <!-- index prox -->
  <joint name="index_prox" type="revolute">
    <hdt id="52" inertia="0.01" kmax="2" kmin="10"/>
    <axis xyz="0 0 1"/>
    <limit effort="4.0" lower="-0.1" upper="2.3" velocity="4.1888"/>
    <origin rpy="0 3.14159265359 0" xyz="0 -0.16325 0.02701"/>
    <parent link="palm"/>
    <child link="index_prox"/>
    <dynamics damping="0.7" friction="0.01"/>
  </joint>
  <transmission name="tran12">
    <type>transmission_interface/SimpleTransmission</type>
    <joint name="index_prox">
      <hardwareInterface>hardware_interface/EffortJointInterface</hardwareInterface>
    </joint>
    <actuator name="motor12">
      <mechanicalReduction>1</mechanicalReduction>
      <hardwareInterface>hardware_interface/EffortJointInterface</hardwareInterface>
    </actuator>
  </transmission>
  <link name="index_prox">
    <collision>
      <origin rpy="0 0 0" xyz="0 0 0"/>
      <geometry>
        <mesh filename="package://hdt_saffir_description/meshes/hdt_6dof_index_prox.STL"/>
      </geometry>
    </collision>
    <visual>
      <origin rpy="0 0 0" xyz="0 0 0"/>
      <geometry>
        <mesh filename="package://hdt_saffir_description/meshes/hdt_6dof_index_prox.STL"/>
      </geometry>
      <material name="orange"/>
    </visual>
    <inertial>
      <origin rpy="0 0 0" xyz="-0.001 -0.02063 0"/>
      <mass value="0.02523"/>
      <!-- <inertia -->
      <!--     ixx="0.000005374" ixy="-0.000000071" ixz="0.0" -->
      <!--     iyy="0.000002921" iyz="0.0" -->
      <!--     izz="0.000004718"/> -->
      <inertia ixx="0.0005374" ixy="-0.0000071" ixz="0.0" iyy="0.0002921" iyz="0.0" izz="0.0004718"/>
    </inertial>
  </link>
  <!-- index med -->
  <joint name="index_med" type="fixed">
    <origin rpy="0 0 0" xyz="-0.00285 -0.04341 0"/>
    <parent link="index_prox"/>
    <child link="index_med"/>
  </joint>
  <link name="index_med">
    <collision>
      <origin rpy="0 0 0" xyz="0 0 0"/>
      <geometry>
        <mesh filename="package://hdt_saffir_description/meshes/hdt_6dof_index_med.STL"/>
      </geometry>
    </collision>
    <visual>
      <origin rpy="0 0 0" xyz="0 0 0"/>
      <geometry>
        <mesh filename="package://hdt_saffir_description/meshes/hdt_6dof_index_med.STL"/>
      </geometry>
      <material name="black"/>
    </visual>
    <inertial>
      <origin rpy="0 0 0" xyz="0.00353 -0.01162 0"/>
      <mass value="0.0085"/>
      <!-- <inertia -->
      <!--     ixx="0.000001639" ixy="0.000000096" ixz="0.0" -->
      <!--     iyy="0.000000981" iyz="0.0" -->
      <!--     izz="0.000001099"/> -->
      <inertia ixx="0.0001639" ixy="0.0000096" ixz="0.0" iyy="0.0000981" iyz="0.0" izz="0.0001099"/>
    </inertial>
  </link>
  <!-- index dist -->
  <joint name="index_dist" type="fixed">
    <origin rpy="0 0 0" xyz="0.0009 -0.02769 0"/>
    <parent link="index_med"/>
    <child link="index_dist"/>
  </joint>
  <link name="index_dist">
    <collision>
      <origin rpy="0 0 0" xyz="0 0 0"/>
      <geometry>
        <mesh filename="package://hdt_saffir_description/meshes/hdt_6dof_index_dist.STL"/>
      </geometry>
    </collision>
    <visual>
      <origin rpy="0 0 0" xyz="0 0 0"/>
      <geometry>
        <mesh filename="package://hdt_saffir_description/meshes/hdt_6dof_index_dist.STL"/>
      </geometry>
      <material name="orange"/>
    </visual>
    <inertial>
      <origin rpy="0 0 0" xyz="0.00131 -0.01323 0"/>
      <mass value="0.0092"/>
      <!-- <inertia -->
      <!--     ixx="0.000000837" ixy="0.0" ixz="0.0" -->
      <!--     iyy="0.000000695" iyz="0.0" -->
      <!--     izz="0.00000066"/> -->
      <inertia ixx="0.000837" ixy="0.0" ixz="0.0" iyy="0.0000695" iyz="0.0" izz="0.000066"/>
    </inertial>
    <origin rpy="0 0 0" xyz="0 -0.08326 -0.00539"/>
  </link>
  <!-- ring prox -->
  <joint name="ring_prox" type="revolute">
    <hdt id="53" inertia="0.01" kmax="2" kmin="10"/>
    <axis xyz="0 0 1"/>
    <limit effort="4.0" lower="-0.1" upper="2.3" velocity="4.1888"/>
    <origin rpy="0 3.14159265359 0" xyz="0 -0.16325 -0.02701"/>
    <parent link="palm"/>
    <child link="ring_prox"/>
    <dynamics damping="0.7" friction="0.01"/>
  </joint>
  <transmission name="tran13">
    <type>transmission_interface/SimpleTransmission</type>
    <joint name="ring_prox">
      <hardwareInterface>hardware_interface/EffortJointInterface</hardwareInterface>
    </joint>
    <actuator name="motor13">
      <mechanicalReduction>1</mechanicalReduction>
      <hardwareInterface>hardware_interface/EffortJointInterfaceyy</hardwareInterface>
    </actuator>
  </transmission>
  <link name="ring_prox">
    <collision>
      <origin rpy="0 0 0" xyz="0 0 0"/>
      <geometry>
        <mesh filename="package://hdt_saffir_description/meshes/hdt_6dof_ring_prox.STL"/>
      </geometry>
    </collision>
    <visual>
      <origin rpy="0 0 0" xyz="0 0 0"/>
      <geometry>
        <mesh filename="package://hdt_saffir_description/meshes/hdt_6dof_ring_prox.STL"/>
      </geometry>
      <material name="orange"/>
    </visual>
    <inertial>
      <origin rpy="0 0 0" xyz="-0.001 -0.02063 0"/>
      <mass value="0.02523"/>
      <!-- <inertia -->
      <!--     ixx="0.000005374" ixy="-0.000000071" ixz="0.0" -->
      <!--     iyy="0.000002921" iyz="0.0" -->
      <!--     izz="0.000004718"/> -->
      <inertia ixx="0.0005374" ixy="-0.0000071" ixz="0.0" iyy="0.0002921" iyz="0.0" izz="0.0004718"/>
    </inertial>
  </link>
  <!-- ring med -->
  <joint name="ring_med" type="fixed">
    <origin rpy="0 0 0" xyz="-0.00285 -0.04341 0"/>
    <parent link="ring_prox"/>
    <child link="ring_med"/>
  </joint>
  <link name="ring_med">
    <collision>
      <origin rpy="0 0 0" xyz="0 0 0"/>
      <geometry>
        <mesh filename="package://hdt_saffir_description/meshes/hdt_6dof_ring_med.STL"/>
      </geometry>
    </collision>
    <visual>
      <origin rpy="0 0 0" xyz="0 0 0"/>
      <geometry>
        <mesh filename="package://hdt_saffir_description/meshes/hdt_6dof_ring_med.STL"/>
      </geometry>
      <material name="black"/>
    </visual>
    <inertial>
      <origin rpy="0 0 0" xyz="0.00353 -0.01162 0"/>
      <mass value="0.0085"/>
      <!-- <inertia -->
      <!--     ixx="0.000001639" ixy="0.000000096" ixz="0.0" -->
      <!--     iyy="0.000000981" iyz="0.0" -->
      <!--     izz="0.000001099"/> -->
      <inertia ixx="0.0001639" ixy="0.0000096" ixz="0.0" iyy="0.0000981" iyz="0.0" izz="0.0001099"/>
    </inertial>
  </link>
  <!-- ring dist -->
  <joint name="ring_dist" type="fixed">
    <origin rpy="0 0 0" xyz="0.0009 -0.02769 0"/>
    <parent link="ring_med"/>
    <child link="ring_dist"/>
  </joint>
  <link name="ring_dist">
    <collision>
      <origin rpy="0 0 0" xyz="0 0 0"/>
      <geometry>
        <mesh filename="package://hdt_saffir_description/meshes/hdt_6dof_ring_dist.STL"/>
      </geometry>
    </collision>
    <visual>
      <origin rpy="0 0 0" xyz="0 0 0"/>
      <geometry>
        <mesh filename="package://hdt_saffir_description/meshes/hdt_6dof_ring_dist.STL"/>
      </geometry>
      <material name="orange"/>
    </visual>
    <inertial>
      <origin rpy="0 0 0" xyz="0.00131 -0.01323 0"/>
      <mass value="0.0092"/>
      <!-- <inertia -->
      <!--     ixx="0.000000837" ixy="0.0" ixz="0.0" -->
      <!--     iyy="0.000000695" iyz="0.0" -->
      <!--     izz="0.00000066"/> -->
      <inertia ixx="0.000837" ixy="0.0" ixz="0.0" iyy="0.000695" iyz="0.0" izz="0.00066"/>
    </inertial>
  </link>
</robot>
